Workbook

Sheet Leeswijzer
A1: Smarteck - Leadtracker en ontwikkelstappen
A2: Twee doelgroepen, een systeem: vastgoedontwikkelaars en energiehubs
A5: Waarvoor is dit?
B6: Dit werkboek houdt vier dingen bij per lead: wie het is, welke overeenkomsten er liggen en in welke status, welke bronnen de lead al met ons heeft gedeeld, en waar wij staan in de ontwikkelstappen.
A8: Invoerbladen | B8: Hier werkt u in.
A9: Leads | B9: Een regel per lead, met doelgroep, herkomst, status en eigenaar.
A10: Contactpersonen | B10: Personen per lead.
A11: Overeenkomsten | B11: Contracten met status, tekendatum en einddatum.
A12: Bronnen | B12: Alles wat een lead heeft aangeleverd, met NDA-markering en verwerkingsstatus.
A13: Voortgang | B13: Een regel per lead per stap; hier zet u de status van elke stap.
A14: Ontwikkelstappen | B14: De standaardstappen per doelgroep. Wijzigt u zelden.
A15: Aannames | B15: Staffel, gateverdeling en kans op FID. Bepaalt de feekolommen op Leads.
A16: Keuzelijsten | B16: Voedt alle keuzemenu's.
A18: Rekenbladen | B18: Deze vullen zichzelf. Niets invoeren.
A19: Overzicht | B19: Per lead: voortgang, volgende stap, getekende en openstaande overeenkomsten, ontvangen en onverwerkte bronnen.
A20: Matrix_Vastgoed | B20: Leads in de rijen, de twintig vastgoedstappen in de kolommen.
A21: Matrix_Energiehub | B21: Leads in de rijen, de negentien hubstappen in de kolommen.
A23: Zo start u een nieuwe lead
A24: 1 | B24: Nieuwe regel op Leads, LeadID oplopend doornummeren (LEAD-003, LEAD-004).
A25: 2 | B25: Op Voortgang alle stappen van de betreffende doelgroep toevoegen: per stap een regel met LeadID en StapID. Kopieer een bestaand blok en pas het LeadID aan.
A26: 3 | B26: Status per stap bijwerken. De matrix en het overzicht volgen automatisch.
A28: Spelregels
A29: 1 | B29: ID's zijn verplicht en uniek: LEAD-001, CON-001, OVK-001, BRN-001, VTG-001.
A30: 2 | B30: StapID heeft altijd het voorvoegsel van de doelgroep: VO-01 tot VO-20 voor vastgoedontwikkelaars, EH-01 tot EH-19 voor energiehubs.
A31: 3 | B31: Datums als echte datum invoeren (jjjj-mm-dd), niet als tekst.
A32: 4 | B32: Slaagkans als percentage tussen 0 en 1.
A33: 5 | B33: Kolomnamen niet wijzigen. De rekenbladen en de webversie koppelen op kolomnaam.
A34: 6 | B34: De cursief grijze eerste regels zijn voorbeelden. Verwijder ze bij ingebruikname.
A36: Samen werken
B37: Zet dit bestand in Teams of SharePoint en werk erin via Excel voor het web; dan kunnen collega's tegelijk invoeren. Voor dagelijks gebruik en snel bijwerken is de webversie (Smarteck_Leadtracker.html) handiger; die exporteert terug naar Excel.

Sheet Keuzelijsten
A1: Keuzelijsten
A2: Voedt alle keuzemenu's. Waarden onderaan een kolom bijplaatsen mag; bestaande waarden hernoemen niet, dat breekt de bestaande invoer.
A4: L_Doelgroep | B4: L_Herkomst | C4: L_Leadstatus | D4: L_Fase | E4: L_Gate | F4: L_Workstream | G4: L_Stapstatus | H4: L_Contracttype | I4: L_Contractstatus | J4: L_Brontype | K4: L_Bronstatus | L4: L_Bruikbaarheid | M4: L_Formaat | N4: L_JaNee | O4: L_Rol | P4: L_Prioriteit | Q4: L_Medewerker
A5: Vastgoedontwikkelaar | B5: Eigen netwerk | C5: Nieuw | D5: Origination | E5: M1 | F5: Commercieel | G5: Niet gestart | H5: NDA | I5: Concept | J5: Energievisie | K5: Opgevraagd | L5: Direct bruikbaar | M5: PDF | N5: Ja | O5: Beslisser | P5: Hoog | Q5: Yusuf
A6: Energiehub | B6: Netbeheerder | C6: In kwalificatie | D6: Feasibility | E6: M2 | F6: Techniek | G6: Loopt | H6: LOI of intentieverklaring | I6: Interne review | J6: Stedenbouwkundig plan | K6: Ontvangen | L6: Bewerking nodig | M6: Excel of CSV | N6: Nee | O6: Budgethouder | P6: Midden | Q6: Jaap van Eck
B7: Kennisplatform Energiehubs | C7: Gekwalificeerd | D7: Development | E7: M3 | F7: Net en congestie | G7: Gereed | H7: Exclusiviteitsovereenkomst | I7: Bij wederpartij | J7: Programma van eisen | K7: In analyse | L7: Beperkt bruikbaar | M7: Word | O7: Beinvloeder | P7: Laag | Q7: Hans Schouten
B8: Provincie of ROM | C8: Propositie uitgebracht | D8: Ready-to-Build | E8: M4 | F8: Juridisch | G8: Geblokkeerd | H8: Opdrachtbevestiging | I8: In onderhandeling | J8: Verbruiksdata of EAN-lijst | K8: Verwerkt | L8: Niet bruikbaar | M8: DWG of DXF | O8: Gatekeeper | Q8: Gertjan de Joode
B9: Gemeente | C9: In onderhandeling | D9: Realisatie | F9: Financieel | G9: Niet van toepassing | H9: Raamovereenkomst | I9: Getekend | J9: Aansluitgegevens en contractvermogens | K9: Onvolledig | L9: Nog niet beoordeeld | M9: GIS of shapefile | O9: Technisch inhoudelijk | Q9: Lucas van Eck
B10: Congres of netwerkevent | C10: Opdracht | D10: On hold | F10: Vergunningen | H10: MoU | I10: Verlopen | J10: Netcapaciteitsinformatie | K10: Niet ontvangen | M10: Afbeelding | O10: Kartrekker hub | Q10: Arnoud
B11: LinkedIn | C11: On hold | D11: Gestopt | F11: Governance | H11: Samenwerkingsovereenkomst | I11: Beeindigd | J11: Congestiebrief netbeheerder | M11: Mondeling of presentatie | O11: Adviseur | Q11: Extern
B12: Inbound via website | C12: Afgewezen | H12: Deelnemersovereenkomst hub | I12: Ingetrokken | J12: Warmtevraagprofiel | M12: Overig
B13: Doorverwijzing partner | C13: Verloren | H13: Anterieure overeenkomst | J13: Meetdata of kwartierwaarden
B14: Aanbesteding | H14: Grondovereenkomst | J14: Kadastrale gegevens
B15: Via Jaap van Eck | H15: ATO netbeheerder | J15: Tekeningen of GIS-bestanden
B16: Via Hans Schouten | H16: GTO of groeps-CSC | J16: Businesscase van de klant
B17: Via Phlip Boswinkel | H17: Warmteleveringsovereenkomst | J17: Vergunningsdossier
B18: Overig | H18: PPA | J18: Deelnemerslijst hub
H19: SLA of uptimeafspraak | J19: Rapport derde partij
H20: EPC-contract | J20: Overig
H21: Assetmanagement-overeenkomst
H22: Verwerkersovereenkomst

Sheet Leads
A1: Leads
A2: Een regel per lead. LeadID is de sleutel waar alle andere tabbladen naar verwijzen. Fee, slaagkans en gewogen fee rekenen zichzelf uit vanuit het tabblad Aannames; overschrijf ze alleen bij een zuivere Engine 1-opdracht.
A4: LeadID | B4: Doelgroep | C4: Organisatie | D4: Projectnaam | E4: Plaats | F4: Provincie | G4: Herkomst van de lead | H4: Aangebracht door | I4: Datum eerste contact | J4: Leadstatus | K4: Ontwikkelfase | L4: Huidige gate | M4: Omvang (woningen of MW) | N4: Verwachte CAPEX (EUR) | O4: Verwachte Smarteck-fee (EUR) | P4: Slaagkans | Q4: Gewogen fee (EUR) | R4: Eigenaar | S4: Prioriteit | T4: Volgende actie | U4: Deadline volgende actie | V4: Opmerkingen | W4: Structureel vermeden piek (kW)
A5: LEAD-001 | B5: Vastgoedontwikkelaar | C5: Ventura City | D5: Ventura City energiesysteem | G5: Eigen netwerk | H5: Yusuf | I5: 2026-04-02 | J5: Opdracht | K5: Feasibility | L5: M2 | M5: 1200 woningen | N5: 12000000 | O5: =IF(OR($N5="",$N5=0),"",MAX(MIN($N5,Aannames!$B$5)*Aannames!$C$5+MAX(0,MIN($N5,Aannames!$B$6)-Aannames!$B$5)*Aannames!$C$6+MAX(0,MIN($N5,Aannames!$B$7)-Aannames!$B$6)*Aannames!$C$7+MAX(0,$N5-Aannames!$B$7)*Aannames!$C$8,Aannames!$B$9)+Aannames!$B$10) -> 555000 | P5: =IF($L5="","",IFERROR(_xlfn.SWITCH($L5,"M1",Aannames!$B$16,"M2",Aannames!$B$17,"M3",Aannames!$B$18,"M4",Aannames!$B$19),"")) -> 0.4 | Q5: =IF(OR($O5="",$P5=""),"",IFERROR(_xlfn.SWITCH($L5,"M1",Aannames!$B$10,"M2",Aannames!$B$10+($O5-Aannames!$B$10)*Aannames!$B$12,"M3",Aannames!$B$10+($O5-Aannames!$B$10)*(Aannames!$B$12+Aannames!$B$13),"M4",$O5),0)+($O5-IFERROR(_xlfn.SWITCH($L5,"M1",Aannames!$B$10,"M2",Aannames!$B$10+($O5-Aannames!$B$10)*Aannames!$B$12,"M3",Aannames!$B$10+($O5-Aannames!$B$10)*(Aannames!$B$12+Aannames!$B$13),"M4",$O5),0))*$P5) -> 332400 | R5: Yusuf | S5: Hoog | T5: Positionpaper afstemmen met Bas Maingay | U5: 2026-09-26 | V5: VOORBEELDRIJ - verwijderen bij ingebruikname. DWA blijft technisch adviseur. | W5: 900
A6: LEAD-002 | B6: Energiehub | C6: Bedrijventerrein Boekelermeer | D6: Hubuitbreiding schakelstation | E6: Alkmaar | F6: Noord-Holland | G6: Kennisplatform Energiehubs | H6: Yusuf | I6: 2026-08-14 | J6: In kwalificatie | K6: Origination | L6: M1 | M6: 8 MW | N6: 4500000 | O6: =IF(OR($N6="",$N6=0),"",MAX(MIN($N6,Aannames!$B$5)*Aannames!$C$5+MAX(0,MIN($N6,Aannames!$B$6)-Aannames!$B$5)*Aannames!$C$6+MAX(0,MIN($N6,Aannames!$B$7)-Aannames!$B$6)*Aannames!$C$7+MAX(0,$N6-Aannames!$B$7)*Aannames!$C$8,Aannames!$B$9)+Aannames!$B$10) -> 250000 | P6: =IF($L6="","",IFERROR(_xlfn.SWITCH($L6,"M1",Aannames!$B$16,"M2",Aannames!$B$17,"M3",Aannames!$B$18,"M4",Aannames!$B$19),"")) -> 0.2 | Q6: =IF(OR($O6="",$P6=""),"",IFERROR(_xlfn.SWITCH($L6,"M1",Aannames!$B$10,"M2",Aannames!$B$10+($O6-Aannames!$B$10)*Aannames!$B$12,"M3",Aannames!$B$10+($O6-Aannames!$B$10)*(Aannames!$B$12+Aannames!$B$13),"M4",$O6),0)+($O6-IFERROR(_xlfn.SWITCH($L6,"M1",Aannames!$B$10,"M2",Aannames!$B$10+($O6-Aannames!$B$10)*Aannames!$B$12,"M3",Aannames!$B$10+($O6-Aannames!$B$10)*(Aannames!$B$12+Aannames!$B$13),"M4",$O6),0))*$P6) -> 70000 | R6: Yusuf | S6: Midden | T6: Werkbezoek aanvragen | U6: 2026-10-03 | V6: Volwassen referentiecase; privaat net plus groeps-CSC. | W6: 550
O7: =IF(OR($N7="",$N7=0),"",MAX(MIN($N7,Aannames!$B$5)*Aannames!$C$5+MAX(0,MIN($N7,Aannames!$B$6)-Aannames!$B$5)*Aannames!$C$6+MAX(0,MIN($N7,Aannames!$B$7)-Aannames!$B$6)*Aannames!$C$7+MAX(0,$N7-Aannames!$B$7)*Aannames!$C$8,Aannames!$B$9)+Aannames!$B$10) | P7: =IF($L7="","",IFERROR(_xlfn.SWITCH($L7,"M1",Aannames!$B$16,"M2",Aannames!$B$17,"M3",Aannames!$B$18,"M4",Aannames!$B$19),"")) | Q7: =IF(OR($O7="",$P7=""),"",IFERROR(_xlfn.SWITCH($L7,"M1",Aannames!$B$10,"M2",Aannames!$B$10+($O7-Aannames!$B$10)*Aannames!$B$12,"M3",Aannames!$B$10+($O7-Aannames!$B$10)*(Aannames!$B$12+Aannames!$B$13),"M4",$O7),0)+($O7-IFERROR(_xlfn.SWITCH($L7,"M1",Aannames!$B$10,"M2",Aannames!$B$10+($O7-Aannames!$B$10)*Aannames!$B$12,"M3",Aannames!$B$10+($O7-Aannames!$B$10)*(Aannames!$B$12+Aannames!$B$13),"M4",$O7),0))*$P7)
O8: =IF(OR($N8="",$N8=0),"",MAX(MIN($N8,Aannames!$B$5)*Aannames!$C$5+MAX(0,MIN($N8,Aannames!$B$6)-Aannames!$B$5)*Aannames!$C$6+MAX(0,MIN($N8,Aannames!$B$7)-Aannames!$B$6)*Aannames!$C$7+MAX(0,$N8-Aannames!$B$7)*Aannames!$C$8,Aannames!$B$9)+Aannames!$B$10) | P8: =IF($L8="","",IFERROR(_xlfn.SWITCH($L8,"M1",Aannames!$B$16,"M2",Aannames!$B$17,"M3",Aannames!$B$18,"M4",Aannames!$B$19),"")) | Q8: =IF(OR($O8="",$P8=""),"",IFERROR(_xlfn.SWITCH($L8,"M1",Aannames!$B$10,"M2",Aannames!$B$10+($O8-Aannames!$B$10)*Aannames!$B$12,"M3",Aannames!$B$10+($O8-Aannames!$B$10)*(Aannames!$B$12+Aannames!$B$13),"M4",$O8),0)+($O8-IFERROR(_xlfn.SWITCH($L8,"M1",Aannames!$B$10,"M2",Aannames!$B$10+($O8-Aannames!$B$10)*Aannames!$B$12,"M3",Aannames!$B$10+($O8-Aannames!$B$10)*(Aannames!$B$12+Aannames!$B$13),"M4",$O8),0))*$P8)
O9: =IF(OR($N9="",$N9=0),"",MAX(MIN($N9,Aannames!$B$5)*Aannames!$C$5+MAX(0,MIN($N9,Aannames!$B$6)-Aannames!$B$5)*Aannames!$C$6+MAX(0,MIN($N9,Aannames!$B$7)-Aannames!$B$6)*Aannames!$C$7+MAX(0,$N9-Aannames!$B$7)*Aannames!$C$8,Aannames!$B$9)+Aannames!$B$10) | P9: =IF($L9="","",IFERROR(_xlfn.SWITCH($L9,"M1",Aannames!$B$16,"M2",Aannames!$B$17,"M3",Aannames!$B$18,"M4",Aannames!$B$19),"")) | Q9: =IF(OR($O9="",$P9=""),"",IFERROR(_xlfn.SWITCH($L9,"M1",Aannames!$B$10,"M2",Aannames!$B$10+($O9-Aannames!$B$10)*Aannames!$B$12,"M3",Aannames!$B$10+($O9-Aannames!$B$10)*(Aannames!$B$12+Aannames!$B$13),"M4",$O9),0)+($O9-IFERROR(_xlfn.SWITCH($L9,"M1",Aannames!$B$10,"M2",Aannames!$B$10+($O9-Aannames!$B$10)*Aannames!$B$12,"M3",Aannames!$B$10+($O9-Aannames!$B$10)*(Aannames!$B$12+Aannames!$B$13),"M4",$O9),0))*$P9)
O10: =IF(OR($N10="",$N10=0),"",MAX(MIN($N10,Aannames!$B$5)*Aannames!$C$5+MAX(0,MIN($N10,Aannames!$B$6)-Aannames!$B$5)*Aannames!$C$6+MAX(0,MIN($N10,Aannames!$B$7)-Aannames!$B$6)*Aannames!$C$7+MAX(0,$N10-Aannames!$B$7)*Aannames!$C$8,Aannames!$B$9)+Aannames!$B$10) | P10: =IF($L10="","",IFERROR(_xlfn.SWITCH($L10,"M1",Aannames!$B$16,"M2",Aannames!$B$17,"M3",Aannames!$B$18,"M4",Aannames!$B$19),"")) | Q10: =IF(OR($O10="",$P10=""),"",IFERROR(_xlfn.SWITCH($L10,"M1",Aannames!$B$10,"M2",Aannames!$B$10+($O10-Aannames!$B$10)*Aannames!$B$12,"M3",Aannames!$B$10+($O10-Aannames!$B$10)*(Aannames!$B$12+Aannames!$B$13),"M4",$O10),0)+($O10-IFERROR(_xlfn.SWITCH($L10,"M1",Aannames!$B$10,"M2",Aannames!$B$10+($O10-Aannames!$B$10)*Aannames!$B$12,"M3",Aannames!$B$10+($O10-Aannames!$B$10)*(Aannames!$B$12+Aannames!$B$13),"M4",$O10),0))*$P10)
O11: =IF(OR($N11="",$N11=0),"",MAX(MIN($N11,Aannames!$B$5)*Aannames!$C$5+MAX(0,MIN($N11,Aannames!$B$6)-Aannames!$B$5)*Aannames!$C$6+MAX(0,MIN($N11,Aannames!$B$7)-Aannames!$B$6)*Aannames!$C$7+MAX(0,$N11-Aannames!$B$7)*Aannames!$C$8,Aannames!$B$9)+Aannames!$B$10) | P11: =IF($L11="","",IFERROR(_xlfn.SWITCH($L11,"M1",Aannames!$B$16,"M2",Aannames!$B$17,"M3",Aannames!$B$18,"M4",Aannames!$B$19),"")) | Q11: =IF(OR($O11="",$P11=""),"",IFERROR(_xlfn.SWITCH($L11,"M1",Aannames!$B$10,"M2",Aannames!$B$10+($O11-Aannames!$B$10)*Aannames!$B$12,"M3",Aannames!$B$10+($O11-Aannames!$B$10)*(Aannames!$B$12+Aannames!$B$13),"M4",$O11),0)+($O11-IFERROR(_xlfn.SWITCH($L11,"M1",Aannames!$B$10,"M2",Aannames!$B$10+($O11-Aannames!$B$10)*Aannames!$B$12,"M3",Aannames!$B$10+($O11-Aannames!$B$10)*(Aannames!$B$12+Aannames!$B$13),"M4",$O11),0))*$P11)
O12: =IF(OR($N12="",$N12=0),"",MAX(MIN($N12,Aannames!$B$5)*Aannames!$C$5+MAX(0,MIN($N12,Aannames!$B$6)-Aannames!$B$5)*Aannames!$C$6+MAX(0,MIN($N12,Aannames!$B$7)-Aannames!$B$6)*Aannames!$C$7+MAX(0,$N12-Aannames!$B$7)*Aannames!$C$8,Aannames!$B$9)+Aannames!$B$10) | P12: =IF($L12="","",IFERROR(_xlfn.SWITCH($L12,"M1",Aannames!$B$16,"M2",Aannames!$B$17,"M3",Aannames!$B$18,"M4",Aannames!$B$19),"")) | Q12: =IF(OR($O12="",$P12=""),"",IFERROR(_xlfn.SWITCH($L12,"M1",Aannames!$B$10,"M2",Aannames!$B$10+($O12-Aannames!$B$10)*Aannames!$B$12,"M3",Aannames!$B$10+($O12-Aannames!$B$10)*(Aannames!$B$12+Aannames!$B$13),"M4",$O12),0)+($O12-IFERROR(_xlfn.SWITCH($L12,"M1",Aannames!$B$10,"M2",Aannames!$B$10+($O12-Aannames!$B$10)*Aannames!$B$12,"M3",Aannames!$B$10+($O12-Aannames!$B$10)*(Aannames!$B$12+Aannames!$B$13),"M4",$O12),0))*$P12)
O13: =IF(OR($N13="",$N13=0),"",MAX(MIN($N13,Aannames!$B$5)*Aannames!$C$5+MAX(0,MIN($N13,Aannames!$B$6)-Aannames!$B$5)*Aannames!$C$6+MAX(0,MIN($N13,Aannames!$B$7)-Aannames!$B$6)*Aannames!$C$7+MAX(0,$N13-Aannames!$B$7)*Aannames!$C$8,Aannames!$B$9)+Aannames!$B$10) | P13: =IF($L13="","",IFERROR(_xlfn.SWITCH($L13,"M1",Aannames!$B$16,"M2",Aannames!$B$17,"M3",Aannames!$B$18,"M4",Aannames!$B$19),"")) | Q13: =IF(OR($O13="",$P13=""),"",IFERROR(_xlfn.SWITCH($L13,"M1",Aannames!$B$10,"M2",Aannames!$B$10+($O13-Aannames!$B$10)*Aannames!$B$12,"M3",Aannames!$B$10+($O13-Aannames!$B$10)*(Aannames!$B$12+Aannames!$B$13),"M4",$O13),0)+($O13-IFERROR(_xlfn.SWITCH($L13,"M1",Aannames!$B$10,"M2",Aannames!$B$10+($O13-Aannames!$B$10)*Aannames!$B$12,"M3",Aannames!$B$10+($O13-Aannames!$B$10)*(Aannames!$B$12+Aannames!$B$13),"M4",$O13),0))*$P13)
O14: =IF(OR($N14="",$N14=0),"",MAX(MIN($N14,Aannames!$B$5)*Aannames!$C$5+MAX(0,MIN($N14,Aannames!$B$6)-Aannames!$B$5)*Aannames!$C$6+MAX(0,MIN($N14,Aannames!$B$7)-Aannames!$B$6)*Aannames!$C$7+MAX(0,$N14-Aannames!$B$7)*Aannames!$C$8,Aannames!$B$9)+Aannames!$B$10) | P14: =IF($L14="","",IFERROR(_xlfn.SWITCH($L14,"M1",Aannames!$B$16,"M2",Aannames!$B$17,"M3",Aannames!$B$18,"M4",Aannames!$B$19),"")) | Q14: =IF(OR($O14="",$P14=""),"",IFERROR(_xlfn.SWITCH($L14,"M1",Aannames!$B$10,"M2",Aannames!$B$10+($O14-Aannames!$B$10)*Aannames!$B$12,"M3",Aannames!$B$10+($O14-Aannames!$B$10)*(Aannames!$B$12+Aannames!$B$13),"M4",$O14),0)+($O14-IFERROR(_xlfn.SWITCH($L14,"M1",Aannames!$B$10,"M2",Aannames!$B$10+($O14-Aannames!$B$10)*Aannames!$B$12,"M3",Aannames!$B$10+($O14-Aannames!$B$10)*(Aannames!$B$12+Aannames!$B$13),"M4",$O14),0))*$P14)
O15: =IF(OR($N15="",$N15=0),"",MAX(MIN($N15,Aannames!$B$5)*Aannames!$C$5+MAX(0,MIN($N15,Aannames!$B$6)-Aannames!$B$5)*Aannames!$C$6+MAX(0,MIN($N15,Aannames!$B$7)-Aannames!$B$6)*Aannames!$C$7+MAX(0,$N15-Aannames!$B$7)*Aannames!$C$8,Aannames!$B$9)+Aannames!$B$10) | P15: =IF($L15="","",IFERROR(_xlfn.SWITCH($L15,"M1",Aannames!$B$16,"M2",Aannames!$B$17,"M3",Aannames!$B$18,"M4",Aannames!$B$19),"")) | Q15: =IF(OR($O15="",$P15=""),"",IFERROR(_xlfn.SWITCH($L15,"M1",Aannames!$B$10,"M2",Aannames!$B$10+($O15-Aannames!$B$10)*Aannames!$B$12,"M3",Aannames!$B$10+($O15-Aannames!$B$10)*(Aannames!$B$12+Aannames!$B$13),"M4",$O15),0)+($O15-IFERROR(_xlfn.SWITCH($L15,"M1",Aannames!$B$10,"M2",Aannames!$B$10+($O15-Aannames!$B$10)*Aannames!$B$12,"M3",Aannames!$B$10+($O15-Aannames!$B$10)*(Aannames!$B$12+Aannames!$B$13),"M4",$O15),0))*$P15)
O16: =IF(OR($N16="",$N16=0),"",MAX(MIN($N16,Aannames!$B$5)*Aannames!$C$5+MAX(0,MIN($N16,Aannames!$B$6)-Aannames!$B$5)*Aannames!$C$6+MAX(0,MIN($N16,Aannames!$B$7)-Aannames!$B$6)*Aannames!$C$7+MAX(0,$N16-Aannames!$B$7)*Aannames!$C$8,Aannames!$B$9)+Aannames!$B$10) | P16: =IF($L16="","",IFERROR(_xlfn.SWITCH($L16,"M1",Aannames!$B$16,"M2",Aannames!$B$17,"M3",Aannames!$B$18,"M4",Aannames!$B$19),"")) | Q16: =IF(OR($O16="",$P16=""),"",IFERROR(_xlfn.SWITCH($L16,"M1",Aannames!$B$10,"M2",Aannames!$B$10+($O16-Aannames!$B$10)*Aannames!$B$12,"M3",Aannames!$B$10+($O16-Aannames!$B$10)*(Aannames!$B$12+Aannames!$B$13),"M4",$O16),0)+($O16-IFERROR(_xlfn.SWITCH($L16,"M1",Aannames!$B$10,"M2",Aannames!$B$10+($O16-Aannames!$B$10)*Aannames!$B$12,"M3",Aannames!$B$10+($O16-Aannames!$B$10)*(Aannames!$B$12+Aannames!$B$13),"M4",$O16),0))*$P16)
O17: =IF(OR($N17="",$N17=0),"",MAX(MIN($N17,Aannames!$B$5)*Aannames!$C$5+MAX(0,MIN($N17,Aannames!$B$6)-Aannames!$B$5)*Aannames!$C$6+MAX(0,MIN($N17,Aannames!$B$7)-Aannames!$B$6)*Aannames!$C$7+MAX(0,$N17-Aannames!$B$7)*Aannames!$C$8,Aannames!$B$9)+Aannames!$B$10) | P17: =IF($L17="","",IFERROR(_xlfn.SWITCH($L17,"M1",Aannames!$B$16,"M2",Aannames!$B$17,"M3",Aannames!$B$18,"M4",Aannames!$B$19),"")) | Q17: =IF(OR($O17="",$P17=""),"",IFERROR(_xlfn.SWITCH($L17,"M1",Aannames!$B$10,"M2",Aannames!$B$10+($O17-Aannames!$B$10)*Aannames!$B$12,"M3",Aannames!$B$10+($O17-Aannames!$B$10)*(Aannames!$B$12+Aannames!$B$13),"M4",$O17),0)+($O17-IFERROR(_xlfn.SWITCH($L17,"M1",Aannames!$B$10,"M2",Aannames!$B$10+($O17-Aannames!$B$10)*Aannames!$B$12,"M3",Aannames!$B$10+($O17-Aannames!$B$10)*(Aannames!$B$12+Aannames!$B$13),"M4",$O17),0))*$P17)
O18: =IF(OR($N18="",$N18=0),"",MAX(MIN($N18,Aannames!$B$5)*Aannames!$C$5+MAX(0,MIN($N18,Aannames!$B$6)-Aannames!$B$5)*Aannames!$C$6+MAX(0,MIN($N18,Aannames!$B$7)-Aannames!$B$6)*Aannames!$C$7+MAX(0,$N18-Aannames!$B$7)*Aannames!$C$8,Aannames!$B$9)+Aannames!$B$10) | P18: =IF($L18="","",IFERROR(_xlfn.SWITCH($L18,"M1",Aannames!$B$16,"M2",Aannames!$B$17,"M3",Aannames!$B$18,"M4",Aannames!$B$19),"")) | Q18: =IF(OR($O18="",$P18=""),"",IFERROR(_xlfn.SWITCH($L18,"M1",Aannames!$B$10,"M2",Aannames!$B$10+($O18-Aannames!$B$10)*Aannames!$B$12,"M3",Aannames!$B$10+($O18-Aannames!$B$10)*(Aannames!$B$12+Aannames!$B$13),"M4",$O18),0)+($O18-IFERROR(_xlfn.SWITCH($L18,"M1",Aannames!$B$10,"M2",Aannames!$B$10+($O18-Aannames!$B$10)*Aannames!$B$12,"M3",Aannames!$B$10+($O18-Aannames!$B$10)*(Aannames!$B$12+Aannames!$B$13),"M4",$O18),0))*$P18)
... O504: =IF(OR($N504="",$N504=0),"",MAX(MIN($N504,Aannames!$B$5)*Aannames!$C$5+MAX(0,MIN($N504,Aannames!$B$6)-Aannames!$B$5)*Aannames!$C$6+MAX(0,MIN($N504,Aannames!$B$7)-Aannames!$B$6)*Aannames!$C$7+MAX(0,$N504-Aannames!$B$7)*Aannames!$C$8,Aannames!$B$9)+Aannames!$B$10) | P504: =IF($L504="","",IFERROR(_xlfn.SWITCH($L504,"M1",Aannames!$B$16,"M2",Aannames!$B$17,"M3",Aannames!$B$18,"M4",Aannames!$B$19),"")) | Q504: =IF(OR($O504="",$P504=""),"",IFERROR(_xlfn.SWITCH($L504,"M1",Aannames!$B$10,"M2",Aannames!$B$10+($O504-Aannames!$B$10)*Aannames!$B$12,"M3",Aannames!$B$10+($O504-Aannames!$B$10)*(Aannames!$B$12+Aannames!$B$13),"M4",$O504),0)+($O504-IFERROR(_xlfn.SWITCH($L504,"M1",Aannames!$B$10,"M2",Aannames!$B$10+($O504-Aannames!$B$10)*Aannames!$B$12,"M3",Aannames!$B$10+($O504-Aannames!$B$10)*(Aannames!$B$12+Aannames!$B$13),"M4",$O504),0))*$P504)

Sheet Aannames
A1: Aannames Engine 2
A2: Deze cellen bepalen de kolommen verwachte fee, slaagkans en gewogen fee op het tabblad Leads. Gelijk aan het blad Aannames in Smarteck_Engine2_Feemodel.xlsx.
A4: Staffel ontwikkelfee (marginale schijven) | E4: Blauwe cijfers op geel zijn invoer. Wijzig hier en het tabblad Leads volgt.
A5: Schijf 1 tot en met (EUR) | B5: 5000000 | C5: 0.05
A6: Schijf 2 tot en met (EUR) | B6: 15000000 | C6: 0.04
A7: Schijf 3 tot en met (EUR) | B7: 40000000 | C7: 0.03
A8: Tarief boven schijf 3 | C8: 0.02
A9: Ondergrens ontwikkelfee M2 t/m M4 (EUR) | B9: 100000
A10: Initiatiefee M1 (vast, EUR) | B10: 25000
A11: Verdeling over de gates
A12: Aandeel M2 | B12: 0.3
A13: Aandeel M3 | B13: 0.3
A14: Aandeel M4 | B14: 0.4
A15: Kans op FID per bereikte gate
A16: M1 bereikt | B16: 0.2
A17: M2 bereikt | B17: 0.4
A18: M3 bereikt | B18: 0.65
A19: M4 bereikt | B19: 0.9

Sheet Contactpersonen
A1: Contactpersonen
A2: Personen per lead. Handig als filter voor wie waar aan tafel zit.
A4: ContactID | B4: LeadID | C4: Naam | D4: Organisatie | E4: Functie | F4: Rol in besluitvorming | G4: E-mail | H4: Telefoon | I4: Relatie-eigenaar | J4: Laatste contact | K4: Opmerkingen
A5: CON-001 | B5: LEAD-001 | C5: Bas Maingay | D5: Ventura City | F5: Beslisser | I5: Yusuf | J5: 2026-09-04 | K5: VOORBEELDRIJ
A6: CON-002 | B6: LEAD-001 | C6: Charlotte Rietdijk | D6: Ventura City | F6: Beinvloeder | I6: Yusuf | J6: 2026-09-04

Sheet Overeenkomsten
A1: Overeenkomsten
A2: Alle documenten met een handtekening of een handtekening in het vooruitzicht, inclusief status en einddatum.
A4: OvereenkomstID | B4: LeadID | C4: Type | D4: Titel | E4: Status | F4: Datum verzonden | G4: Datum getekend | H4: Ingangsdatum | I4: Einddatum | J4: Looptijd (mnd) | K4: Contractwaarde (EUR) | L4: Ondertekenaar Smarteck | M4: Ondertekenaar wederpartij | N4: Documentlocatie | O4: Actie vereist | P4: Opmerkingen
A5: OVK-001 | B5: LEAD-001 | C5: NDA | D5: NDA Ventura City | E5: Getekend | F5: 2026-04-02 | G5: 2026-04-08 | H5: 2026-04-08 | I5: 2029-04-08 | J5: 36 | K5: 0 | L5: Yusuf | O5: Nee | P5: VOORBEELDRIJ
A6: OVK-002 | B6: LEAD-001 | C6: MoU | D6: MoU v0.6 Ventura City | E6: In onderhandeling | F6: 2026-08-28 | K6: 0 | L6: Yusuf | O6: Ja | P6: Artikelverwijzingen afgestemd met positionpaper.

Sheet Bronnen
A1: Bronnen
A2: Register van alles wat een lead met ons heeft gedeeld. Dit is tegelijk het bewijs van wat er onder NDA valt.
A4: BronID | B4: LeadID | C4: Brontype | D4: Titel of bestandsnaam | E4: Aangeleverd door | F4: Datum ontvangen | G4: Formaat | H4: Status | I4: Bruikbaarheid | J4: Vertrouwelijk | K4: Onder NDA | L4: Bestandslocatie | M4: Gebruikt voor stap | N4: Beoordeeld door | O4: Opmerkingen
A5: BRN-001 | B5: LEAD-001 | C5: Energievisie | D5: Energievisie Ventura City | E5: Bas Maingay | F5: 2026-04-15 | G5: PDF | H5: In analyse | I5: Bewerking nodig | J5: Ja | K5: Ja | M5: VO-03 | N5: Yusuf | O5: VOORBEELDRIJ - piekreductiecijfers in merkmateriaal blijven placeholder tot dit is verwerkt.
A6: BRN-002 | B6: LEAD-002 | C6: Aansluitgegevens en contractvermogens | D6: EAN-lijst deelnemers Boekelermeer | G6: Excel of CSV | H6: Opgevraagd | I6: Nog niet beoordeeld | J6: Ja | K6: Nee | M6: EH-04 | N6: Yusuf

Sheet Ontwikkelstappen
A1: Ontwikkelstappen
A2: De stappenbibliotheek: twee sporen, een per doelgroep. Dit is de standaard die u per lead afvinkt. Stappen bijplaatsen mag; nummering aaneengesloten houden.
A4: StapID | B4: Doelgroep | C4: Nr | D4: Stap | E4: Workstream | F4: Gate | G4: Verplicht | H4: Doorlooptijd (weken) | I4: Toelichting
A5: VO-01 | B5: Vastgoedontwikkelaar | C5: 1 | D5: Lead gekwalificeerd | E5: Commercieel | F5: M1 | G5: Ja | I5: Gebiedsontwikkeling, fase en besluitvormingsmoment vastgesteld
A6: VO-02 | B6: Vastgoedontwikkelaar | C6: 2 | D6: NDA getekend | E6: Juridisch | F6: M1 | G6: Ja | I6: Voorwaarde voor het opvragen van bronnen
A7: VO-03 | B7: Vastgoedontwikkelaar | C7: 3 | D7: Bronnen opgevraagd en ontvangen | E7: Commercieel | F7: M1 | G7: Ja | I7: Energievisie, stedenbouwkundig plan, programma van eisen
A8: VO-04 | B8: Vastgoedontwikkelaar | C8: 4 | D8: Quickscan netcapaciteit en congestiestatus | E8: Net en congestie | F8: M1 | G8: Ja | I8: Capaciteitskaart netbeheerder, wachtrijpositie, transportbeperking
A9: VO-05 | B9: Vastgoedontwikkelaar | C9: 5 | D9: Vraagprofiel elektriciteit en warmte | E9: Techniek | F9: M1 | G9: Ja | I9: Twee stromen in een profiel; basis voor het hele ontwerp
A10: VO-06 | B10: Vastgoedontwikkelaar | C10: 6 | D10: Piek- en gelijktijdigheidsanalyse | E10: Techniek | F10: M1 | G10: Ja | I10: Onderbouwt de piekreductie die wij aan de netbeheerder beloven
A11: VO-07 | B11: Vastgoedontwikkelaar | C11: 7 | D11: Eerste gesprek netbeheerder | E11: Net en congestie | F11: M1 | G11: Ja | I11: Wegnemen en spiegelen als openingsvraag
A12: VO-08 | B12: Vastgoedontwikkelaar | C12: 8 | D12: Routekeuze-scan vier routes | E12: Commercieel | F12: M1 | G12: Ja | I12: Betaald beslisinstrument; eigendom, balansimpact, regieverlies
A13: VO-09 | B13: Vastgoedontwikkelaar | C13: 9 | D13: Propositie uitgebracht | E13: Commercieel | F13: M1 | G13: Ja | I13: Engine 1 of gedelegeerde ontwikkeling
A14: VO-10 | B14: Vastgoedontwikkelaar | C14: 10 | D14: Opdrachtbevestiging Engine 1 | E14: Juridisch | F14: M1 | G14: Ja | I14: Eerste facturabele opdracht
A15: VO-11 | B15: Vastgoedontwikkelaar | C15: 11 | D15: Systeemconcept twee stromen | E15: Techniek | F15: M2 | G15: Ja | I15: Warmte is het middel, netbalans het doel
A16: VO-12 | B16: Vastgoedontwikkelaar | C16: 12 | D16: Businesscase eerste orde | E16: Financieel | F16: M2 | G16: Ja | I16: Bankable maken; onrendabele top expliciet
... A43: EH-19 | B43: Energiehub | C43: 19 | D43: Exploitatie- en beheerovereenkomst | E43: Governance | F43: M4 | G43: Nee | I43: Assetmanagement en O&M

Sheet Voortgang
A1: Voortgang
A2: Een regel per lead per stap. Alleen de kolommen Status, datums en verantwoordelijke invullen; Stapnr, Stap, Workstream, Openstaand nr en Sleutel rekenen zichzelf uit.
A4: VoortgangID | B4: LeadID | C4: StapID | D4: Stapnr | E4: Stap | F4: Workstream | G4: Status | H4: Startdatum | I4: Gepland gereed | J4: Werkelijk gereed | K4: Verantwoordelijke | L4: Openstaand nr | M4: Sleutel | N4: Opmerkingen
A5: VTG-001 | B5: LEAD-001 | C5: VO-01 | D5: =IFERROR(INDEX(Ontwikkelstappen!$C$5:$C$504,MATCH($C5,Ontwikkelstappen!$A$5:$A$504,0)),"") -> 1 | E5: =IFERROR(INDEX(Ontwikkelstappen!$D$5:$D$504,MATCH($C5,Ontwikkelstappen!$A$5:$A$504,0)),"") -> Lead gekwalificeerd | F5: =IFERROR(INDEX(Ontwikkelstappen!$E$5:$E$504,MATCH($C5,Ontwikkelstappen!$A$5:$A$504,0)),"") -> Commercieel | G5: Gereed | K5: Yusuf | L5: =IF($D5="",9999,IF(OR($G5="Gereed",$G5="Niet van toepassing"),9999,$D5)) -> 9999 | M5: =IF($B5="","",$B5&"|"&TEXT($D5,"00")) -> LEAD-001|01
A6: VTG-002 | B6: LEAD-001 | C6: VO-02 | D6: =IFERROR(INDEX(Ontwikkelstappen!$C$5:$C$504,MATCH($C6,Ontwikkelstappen!$A$5:$A$504,0)),"") -> 2 | E6: =IFERROR(INDEX(Ontwikkelstappen!$D$5:$D$504,MATCH($C6,Ontwikkelstappen!$A$5:$A$504,0)),"") -> NDA getekend | F6: =IFERROR(INDEX(Ontwikkelstappen!$E$5:$E$504,MATCH($C6,Ontwikkelstappen!$A$5:$A$504,0)),"") -> Juridisch | G6: Gereed | K6: Yusuf | L6: =IF($D6="",9999,IF(OR($G6="Gereed",$G6="Niet van toepassing"),9999,$D6)) -> 9999 | M6: =IF($B6="","",$B6&"|"&TEXT($D6,"00")) -> LEAD-001|02
A7: VTG-003 | B7: LEAD-001 | C7: VO-03 | D7: =IFERROR(INDEX(Ontwikkelstappen!$C$5:$C$504,MATCH($C7,Ontwikkelstappen!$A$5:$A$504,0)),"") -> 3 | E7: =IFERROR(INDEX(Ontwikkelstappen!$D$5:$D$504,MATCH($C7,Ontwikkelstappen!$A$5:$A$504,0)),"") -> Bronnen opgevraagd en ontvangen | F7: =IFERROR(INDEX(Ontwikkelstappen!$E$5:$E$504,MATCH($C7,Ontwikkelstappen!$A$5:$A$504,0)),"") -> Commercieel | G7: Loopt | K7: Yusuf | L7: =IF($D7="",9999,IF(OR($G7="Gereed",$G7="Niet van toepassing"),9999,$D7)) -> 3 | M7: =IF($B7="","",$B7&"|"&TEXT($D7,"00")) -> LEAD-001|03
A8: VTG-004 | B8: LEAD-001 | C8: VO-04 | D8: =IFERROR(INDEX(Ontwikkelstappen!$C$5:$C$504,MATCH($C8,Ontwikkelstappen!$A$5:$A$504,0)),"") -> 4 | E8: =IFERROR(INDEX(Ontwikkelstappen!$D$5:$D$504,MATCH($C8,Ontwikkelstappen!$A$5:$A$504,0)),"") -> Quickscan netcapaciteit en congestiestatus | F8: =IFERROR(INDEX(Ontwikkelstappen!$E$5:$E$504,MATCH($C8,Ontwikkelstappen!$A$5:$A$504,0)),"") -> Net en congestie | G8: Gereed | K8: Yusuf | L8: =IF($D8="",9999,IF(OR($G8="Gereed",$G8="Niet van toepassing"),9999,$D8)) -> 9999 | M8: =IF($B8="","",$B8&"|"&TEXT($D8,"00")) -> LEAD-001|04
A9: VTG-005 | B9: LEAD-001 | C9: VO-05 | D9: =IFERROR(INDEX(Ontwikkelstappen!$C$5:$C$504,MATCH($C9,Ontwikkelstappen!$A$5:$A$504,0)),"") -> 5 | E9: =IFERROR(INDEX(Ontwikkelstappen!$D$5:$D$504,MATCH($C9,Ontwikkelstappen!$A$5:$A$504,0)),"") -> Vraagprofiel elektriciteit en warmte | F9: =IFERROR(INDEX(Ontwikkelstappen!$E$5:$E$504,MATCH($C9,Ontwikkelstappen!$A$5:$A$504,0)),"") -> Techniek | G9: Loopt | K9: Yusuf | L9: =IF($D9="",9999,IF(OR($G9="Gereed",$G9="Niet van toepassing"),9999,$D9)) -> 5 | M9: =IF($B9="","",$B9&"|"&TEXT($D9,"00")) -> LEAD-001|05
A10: VTG-006 | B10: LEAD-001 | C10: VO-06 | D10: =IFERROR(INDEX(Ontwikkelstappen!$C$5:$C$504,MATCH($C10,Ontwikkelstappen!$A$5:$A$504,0)),"") -> 6 | E10: =IFERROR(INDEX(Ontwikkelstappen!$D$5:$D$504,MATCH($C10,Ontwikkelstappen!$A$5:$A$504,0)),"") -> Piek- en gelijktijdigheidsanalyse | F10: =IFERROR(INDEX(Ontwikkelstappen!$E$5:$E$504,MATCH($C10,Ontwikkelstappen!$A$5:$A$504,0)),"") -> Techniek | G10: Niet gestart | K10: Yusuf | L10: =IF($D10="",9999,IF(OR($G10="Gereed",$G10="Niet van toepassing"),9999,$D10)) -> 6 | M10: =IF($B10="","",$B10&"|"&TEXT($D10,"00")) -> LEAD-001|06
A11: VTG-007 | B11: LEAD-001 | C11: VO-07 | D11: =IFERROR(INDEX(Ontwikkelstappen!$C$5:$C$504,MATCH($C11,Ontwikkelstappen!$A$5:$A$504,0)),"") -> 7 | E11: =IFERROR(INDEX(Ontwikkelstappen!$D$5:$D$504,MATCH($C11,Ontwikkelstappen!$A$5:$A$504,0)),"") -> Eerste gesprek netbeheerder | F11: =IFERROR(INDEX(Ontwikkelstappen!$E$5:$E$504,MATCH($C11,Ontwikkelstappen!$A$5:$A$504,0)),"") -> Net en congestie | G11: Gereed | K11: Yusuf | L11: =IF($D11="",9999,IF(OR($G11="Gereed",$G11="Niet van toepassing"),9999,$D11)) -> 9999 | M11: =IF($B11="","",$B11&"|"&TEXT($D11,"00")) -> LEAD-001|07
A12: VTG-008 | B12: LEAD-001 | C12: VO-08 | D12: =IFERROR(INDEX(Ontwikkelstappen!$C$5:$C$504,MATCH($C12,Ontwikkelstappen!$A$5:$A$504,0)),"") -> 8 | E12: =IFERROR(INDEX(Ontwikkelstappen!$D$5:$D$504,MATCH($C12,Ontwikkelstappen!$A$5:$A$504,0)),"") -> Routekeuze-scan vier routes | F12: =IFERROR(INDEX(Ontwikkelstappen!$E$5:$E$504,MATCH($C12,Ontwikkelstappen!$A$5:$A$504,0)),"") -> Commercieel | G12: Niet gestart | K12: Yusuf | L12: =IF($D12="",9999,IF(OR($G12="Gereed",$G12="Niet van toepassing"),9999,$D12)) -> 8 | M12: =IF($B12="","",$B12&"|"&TEXT($D12,"00")) -> LEAD-001|08
A13: VTG-009 | B13: LEAD-001 | C13: VO-09 | D13: =IFERROR(INDEX(Ontwikkelstappen!$C$5:$C$504,MATCH($C13,Ontwikkelstappen!$A$5:$A$504,0)),"") -> 9 | E13: =IFERROR(INDEX(Ontwikkelstappen!$D$5:$D$504,MATCH($C13,Ontwikkelstappen!$A$5:$A$504,0)),"") -> Propositie uitgebracht | F13: =IFERROR(INDEX(Ontwikkelstappen!$E$5:$E$504,MATCH($C13,Ontwikkelstappen!$A$5:$A$504,0)),"") -> Commercieel | G13: Gereed | K13: Yusuf | L13: =IF($D13="",9999,IF(OR($G13="Gereed",$G13="Niet van toepassing"),9999,$D13)) -> 9999 | M13: =IF($B13="","",$B13&"|"&TEXT($D13,"00")) -> LEAD-001|09
A14: VTG-010 | B14: LEAD-001 | C14: VO-10 | D14: =IFERROR(INDEX(Ontwikkelstappen!$C$5:$C$504,MATCH($C14,Ontwikkelstappen!$A$5:$A$504,0)),"") -> 10 | E14: =IFERROR(INDEX(Ontwikkelstappen!$D$5:$D$504,MATCH($C14,Ontwikkelstappen!$A$5:$A$504,0)),"") -> Opdrachtbevestiging Engine 1 | F14: =IFERROR(INDEX(Ontwikkelstappen!$E$5:$E$504,MATCH($C14,Ontwikkelstappen!$A$5:$A$504,0)),"") -> Juridisch | G14: Gereed | K14: Yusuf | L14: =IF($D14="",9999,IF(OR($G14="Gereed",$G14="Niet van toepassing"),9999,$D14)) -> 9999 | M14: =IF($B14="","",$B14&"|"&TEXT($D14,"00")) -> LEAD-001|10
A15: VTG-011 | B15: LEAD-001 | C15: VO-11 | D15: =IFERROR(INDEX(Ontwikkelstappen!$C$5:$C$504,MATCH($C15,Ontwikkelstappen!$A$5:$A$504,0)),"") -> 11 | E15: =IFERROR(INDEX(Ontwikkelstappen!$D$5:$D$504,MATCH($C15,Ontwikkelstappen!$A$5:$A$504,0)),"") -> Systeemconcept twee stromen | F15: =IFERROR(INDEX(Ontwikkelstappen!$E$5:$E$504,MATCH($C15,Ontwikkelstappen!$A$5:$A$504,0)),"") -> Techniek | G15: Niet gestart | K15: Yusuf | L15: =IF($D15="",9999,IF(OR($G15="Gereed",$G15="Niet van toepassing"),9999,$D15)) -> 11 | M15: =IF($B15="","",$B15&"|"&TEXT($D15,"00")) -> LEAD-001|11
A16: VTG-012 | B16: LEAD-001 | C16: VO-12 | D16: =IFERROR(INDEX(Ontwikkelstappen!$C$5:$C$504,MATCH($C16,Ontwikkelstappen!$A$5:$A$504,0)),"") -> 12 | E16: =IFERROR(INDEX(Ontwikkelstappen!$D$5:$D$504,MATCH($C16,Ontwikkelstappen!$A$5:$A$504,0)),"") -> Businesscase eerste orde | F16: =IFERROR(INDEX(Ontwikkelstappen!$E$5:$E$504,MATCH($C16,Ontwikkelstappen!$A$5:$A$504,0)),"") -> Financieel | G16: Niet gestart | K16: Yusuf | L16: =IF($D16="",9999,IF(OR($G16="Gereed",$G16="Niet van toepassing"),9999,$D16)) -> 12 | M16: =IF($B16="","",$B16&"|"&TEXT($D16,"00")) -> LEAD-001|12
... A43: VTG-039 | B43: LEAD-002 | C43: EH-19 | D43: =IFERROR(INDEX(Ontwikkelstappen!$C$5:$C$504,MATCH($C43,Ontwikkelstappen!$A$5:$A$504,0)),"") -> 19 | E43: =IFERROR(INDEX(Ontwikkelstappen!$D$5:$D$504,MATCH($C43,Ontwikkelstappen!$A$5:$A$504,0)),"") -> Exploitatie- en beheerovereenkomst | F43: =IFERROR(INDEX(Ontwikkelstappen!$E$5:$E$504,MATCH($C43,Ontwikkelstappen!$A$5:$A$504,0)),"") -> Governance | G43: Niet gestart | K43: Yusuf | L43: =IF($D43="",9999,IF(OR($G43="Gereed",$G43="Niet van toepassing"),9999,$D43)) -> 19 | M43: =IF($B43="","",$B43&"|"&TEXT($D43,"00")) -> LEAD-002|19

Sheet Overzicht
A1: Overzicht per lead
A2: Rekent zich volledig uit op basis van de tabbladen Leads, Voortgang, Overeenkomsten en Bronnen. Niets invullen op dit blad.
A4: LeadID | B4: Organisatie | C4: Doelgroep | D4: Leadstatus | E4: Gate | F4: Stappen totaal | G4: Gereed | H4: Loopt | I4: Geblokkeerd | J4: Voortgang | K4: Volgende stap | L4: Overeenkomsten getekend | M4: Overeenkomsten open | N4: Bronnen ontvangen | O4: Bronnen nog te verwerken | P4: Gewogen fee (EUR)
A5: =IFERROR(IF(INDEX(Leads!$A$5:$A$504,1)="","",INDEX(Leads!$A$5:$A$504,1)),"") -> LEAD-001 | B5: =IF($A5="","",INDEX(Leads!$C$5:$C$504,1)) -> Ventura City | C5: =IF($A5="","",INDEX(Leads!$B$5:$B$504,1)) -> Vastgoedontwikkelaar | D5: =IF($A5="","",INDEX(Leads!$J$5:$J$504,1)) -> Opdracht | E5: =IF($A5="","",INDEX(Leads!$L$5:$L$504,1)) -> M2 | F5: =IF($A5="","",COUNTIFS(Voortgang!$B$5:$B$504,$A5)) -> 20 | G5: =IF($A5="","",COUNTIFS(Voortgang!$B$5:$B$504,$A5,Voortgang!$G$5:$G$504,"Gereed")) -> 6 | H5: =IF($A5="","",COUNTIFS(Voortgang!$B$5:$B$504,$A5,Voortgang!$G$5:$G$504,"Loopt")) -> 2 | I5: =IF($A5="","",COUNTIFS(Voortgang!$B$5:$B$504,$A5,Voortgang!$G$5:$G$504,"Geblokkeerd")) -> 0 | J5: =IF($A5="","",IFERROR($G5/($F5-COUNTIFS(Voortgang!$B$5:$B$504,$A5,Voortgang!$G$5:$G$504,"Niet van toepassing")),"")) -> 0.3 | K5: =IF($A5="","",IFERROR(IF(_xlfn.MINIFS(Voortgang!$L$5:$L$504,Voortgang!$B$5:$B$504,$A5)=9999,"Alle stappen afgerond",INDEX(Voortgang!$E$5:$E$504,MATCH($A5&"|"&TEXT(_xlfn.MINIFS(Voortgang!$L$5:$L$504,Voortgang!$B$5:$B$504,$A5),"00"),Voortgang!$M$5:$M$504,0))),"")) -> Bronnen opgevraagd en ontvangen | L5: =IF($A5="","",COUNTIFS(Overeenkomsten!$B$5:$B$504,$A5,Overeenkomsten!$E$5:$E$504,"Getekend")) -> 1 | M5: =IF($A5="","",COUNTIFS(Overeenkomsten!$B$5:$B$504,$A5)-$L5) -> 1 | N5: =IF($A5="","",COUNTIFS(Bronnen!$B$5:$B$504,$A5,Bronnen!$H$5:$H$504,"Ontvangen")+COUNTIFS(Bronnen!$B$5:$B$504,$A5,Bronnen!$H$5:$H$504,"In analyse")+COUNTIFS(Bronnen!$B$5:$B$504,$A5,Bronnen!$H$5:$H$504,"Verwerkt")) -> 1 | O5: =IF($A5="","",COUNTIFS(Bronnen!$B$5:$B$504,$A5,Bronnen!$H$5:$H$504,"Ontvangen")+COUNTIFS(Bronnen!$B$5:$B$504,$A5,Bronnen!$H$5:$H$504,"In analyse")) -> 1 | P5: =IF($A5="","",INDEX(Leads!$Q$5:$Q$504,1)) -> 332400
A6: =IFERROR(IF(INDEX(Leads!$A$5:$A$504,2)="","",INDEX(Leads!$A$5:$A$504,2)),"") -> LEAD-002 | B6: =IF($A6="","",INDEX(Leads!$C$5:$C$504,2)) -> Bedrijventerrein Boekelermeer | C6: =IF($A6="","",INDEX(Leads!$B$5:$B$504,2)) -> Energiehub | D6: =IF($A6="","",INDEX(Leads!$J$5:$J$504,2)) -> In kwalificatie | E6: =IF($A6="","",INDEX(Leads!$L$5:$L$504,2)) -> M1 | F6: =IF($A6="","",COUNTIFS(Voortgang!$B$5:$B$504,$A6)) -> 19 | G6: =IF($A6="","",COUNTIFS(Voortgang!$B$5:$B$504,$A6,Voortgang!$G$5:$G$504,"Gereed")) -> 1 | H6: =IF($A6="","",COUNTIFS(Voortgang!$B$5:$B$504,$A6,Voortgang!$G$5:$G$504,"Loopt")) -> 2 | I6: =IF($A6="","",COUNTIFS(Voortgang!$B$5:$B$504,$A6,Voortgang!$G$5:$G$504,"Geblokkeerd")) -> 0 | J6: =IF($A6="","",IFERROR($G6/($F6-COUNTIFS(Voortgang!$B$5:$B$504,$A6,Voortgang!$G$5:$G$504,"Niet van toepassing")),"")) -> 0.052631579 | K6: =IF($A6="","",IFERROR(IF(_xlfn.MINIFS(Voortgang!$L$5:$L$504,Voortgang!$B$5:$B$504,$A6)=9999,"Alle stappen afgerond",INDEX(Voortgang!$E$5:$E$504,MATCH($A6&"|"&TEXT(_xlfn.MINIFS(Voortgang!$L$5:$L$504,Voortgang!$B$5:$B$504,$A6),"00"),Voortgang!$M$5:$M$504,0))),"")) -> Kartrekker en deelnemers in beeld | L6: =IF($A6="","",COUNTIFS(Overeenkomsten!$B$5:$B$504,$A6,Overeenkomsten!$E$5:$E$504,"Getekend")) -> 0 | M6: =IF($A6="","",COUNTIFS(Overeenkomsten!$B$5:$B$504,$A6)-$L6) -> 0 | N6: =IF($A6="","",COUNTIFS(Bronnen!$B$5:$B$504,$A6,Bronnen!$H$5:$H$504,"Ontvangen")+COUNTIFS(Bronnen!$B$5:$B$504,$A6,Bronnen!$H$5:$H$504,"In analyse")+COUNTIFS(Bronnen!$B$5:$B$504,$A6,Bronnen!$H$5:$H$504,"Verwerkt")) -> 0 | O6: =IF($A6="","",COUNTIFS(Bronnen!$B$5:$B$504,$A6,Bronnen!$H$5:$H$504,"Ontvangen")+COUNTIFS(Bronnen!$B$5:$B$504,$A6,Bronnen!$H$5:$H$504,"In analyse")) -> 0 | P6: =IF($A6="","",INDEX(Leads!$Q$5:$Q$504,2)) -> 70000
A7: =IFERROR(IF(INDEX(Leads!$A$5:$A$504,3)="","",INDEX(Leads!$A$5:$A$504,3)),"") | B7: =IF($A7="","",INDEX(Leads!$C$5:$C$504,3)) | C7: =IF($A7="","",INDEX(Leads!$B$5:$B$504,3)) | D7: =IF($A7="","",INDEX(Leads!$J$5:$J$504,3)) | E7: =IF($A7="","",INDEX(Leads!$L$5:$L$504,3)) | F7: =IF($A7="","",COUNTIFS(Voortgang!$B$5:$B$504,$A7)) | G7: =IF($A7="","",COUNTIFS(Voortgang!$B$5:$B$504,$A7,Voortgang!$G$5:$G$504,"Gereed")) | H7: =IF($A7="","",COUNTIFS(Voortgang!$B$5:$B$504,$A7,Voortgang!$G$5:$G$504,"Loopt")) | I7: =IF($A7="","",COUNTIFS(Voortgang!$B$5:$B$504,$A7,Voortgang!$G$5:$G$504,"Geblokkeerd")) | J7: =IF($A7="","",IFERROR($G7/($F7-COUNTIFS(Voortgang!$B$5:$B$504,$A7,Voortgang!$G$5:$G$504,"Niet van toepassing")),"")) | K7: =IF($A7="","",IFERROR(IF(_xlfn.MINIFS(Voortgang!$L$5:$L$504,Voortgang!$B$5:$B$504,$A7)=9999,"Alle stappen afgerond",INDEX(Voortgang!$E$5:$E$504,MATCH($A7&"|"&TEXT(_xlfn.MINIFS(Voortgang!$L$5:$L$504,Voortgang!$B$5:$B$504,$A7),"00"),Voortgang!$M$5:$M$504,0))),"")) | L7: =IF($A7="","",COUNTIFS(Overeenkomsten!$B$5:$B$504,$A7,Overeenkomsten!$E$5:$E$504,"Getekend")) | M7: =IF($A7="","",COUNTIFS(Overeenkomsten!$B$5:$B$504,$A7)-$L7) | N7: =IF($A7="","",COUNTIFS(Bronnen!$B$5:$B$504,$A7,Bronnen!$H$5:$H$504,"Ontvangen")+COUNTIFS(Bronnen!$B$5:$B$504,$A7,Bronnen!$H$5:$H$504,"In analyse")+COUNTIFS(Bronnen!$B$5:$B$504,$A7,Bronnen!$H$5:$H$504,"Verwerkt")) | O7: =IF($A7="","",COUNTIFS(Bronnen!$B$5:$B$504,$A7,Bronnen!$H$5:$H$504,"Ontvangen")+COUNTIFS(Bronnen!$B$5:$B$504,$A7,Bronnen!$H$5:$H$504,"In analyse")) | P7: =IF($A7="","",INDEX(Leads!$Q$5:$Q$504,3))
A8: =IFERROR(IF(INDEX(Leads!$A$5:$A$504,4)="","",INDEX(Leads!$A$5:$A$504,4)),"") | B8: =IF($A8="","",INDEX(Leads!$C$5:$C$504,4)) | C8: =IF($A8="","",INDEX(Leads!$B$5:$B$504,4)) | D8: =IF($A8="","",INDEX(Leads!$J$5:$J$504,4)) | E8: =IF($A8="","",INDEX(Leads!$L$5:$L$504,4)) | F8: =IF($A8="","",COUNTIFS(Voortgang!$B$5:$B$504,$A8)) | G8: =IF($A8="","",COUNTIFS(Voortgang!$B$5:$B$504,$A8,Voortgang!$G$5:$G$504,"Gereed")) | H8: =IF($A8="","",COUNTIFS(Voortgang!$B$5:$B$504,$A8,Voortgang!$G$5:$G$504,"Loopt")) | I8: =IF($A8="","",COUNTIFS(Voortgang!$B$5:$B$504,$A8,Voortgang!$G$5:$G$504,"Geblokkeerd")) | J8: =IF($A8="","",IFERROR($G8/($F8-COUNTIFS(Voortgang!$B$5:$B$504,$A8,Voortgang!$G$5:$G$504,"Niet van toepassing")),"")) | K8: =IF($A8="","",IFERROR(IF(_xlfn.MINIFS(Voortgang!$L$5:$L$504,Voortgang!$B$5:$B$504,$A8)=9999,"Alle stappen afgerond",INDEX(Voortgang!$E$5:$E$504,MATCH($A8&"|"&TEXT(_xlfn.MINIFS(Voortgang!$L$5:$L$504,Voortgang!$B$5:$B$504,$A8),"00"),Voortgang!$M$5:$M$504,0))),"")) | L8: =IF($A8="","",COUNTIFS(Overeenkomsten!$B$5:$B$504,$A8,Overeenkomsten!$E$5:$E$504,"Getekend")) | M8: =IF($A8="","",COUNTIFS(Overeenkomsten!$B$5:$B$504,$A8)-$L8) | N8: =IF($A8="","",COUNTIFS(Bronnen!$B$5:$B$504,$A8,Bronnen!$H$5:$H$504,"Ontvangen")+COUNTIFS(Bronnen!$B$5:$B$504,$A8,Bronnen!$H$5:$H$504,"In analyse")+COUNTIFS(Bronnen!$B$5:$B$504,$A8,Bronnen!$H$5:$H$504,"Verwerkt")) | O8: =IF($A8="","",COUNTIFS(Bronnen!$B$5:$B$504,$A8,Bronnen!$H$5:$H$504,"Ontvangen")+COUNTIFS(Bronnen!$B$5:$B$504,$A8,Bronnen!$H$5:$H$504,"In analyse")) | P8: =IF($A8="","",INDEX(Leads!$Q$5:$Q$504,4))
A9: =IFERROR(IF(INDEX(Leads!$A$5:$A$504,5)="","",INDEX(Leads!$A$5:$A$504,5)),"") | B9: =IF($A9="","",INDEX(Leads!$C$5:$C$504,5)) | C9: =IF($A9="","",INDEX(Leads!$B$5:$B$504,5)) | D9: =IF($A9="","",INDEX(Leads!$J$5:$J$504,5)) | E9: =IF($A9="","",INDEX(Leads!$L$5:$L$504,5)) | F9: =IF($A9="","",COUNTIFS(Voortgang!$B$5:$B$504,$A9)) | G9: =IF($A9="","",COUNTIFS(Voortgang!$B$5:$B$504,$A9,Voortgang!$G$5:$G$504,"Gereed")) | H9: =IF($A9="","",COUNTIFS(Voortgang!$B$5:$B$504,$A9,Voortgang!$G$5:$G$504,"Loopt")) | I9: =IF($A9="","",COUNTIFS(Voortgang!$B$5:$B$504,$A9,Voortgang!$G$5:$G$504,"Geblokkeerd")) | J9: =IF($A9="","",IFERROR($G9/($F9-COUNTIFS(Voortgang!$B$5:$B$504,$A9,Voortgang!$G$5:$G$504,"Niet van toepassing")),"")) | K9: =IF($A9="","",IFERROR(IF(_xlfn.MINIFS(Voortgang!$L$5:$L$504,Voortgang!$B$5:$B$504,$A9)=9999,"Alle stappen afgerond",INDEX(Voortgang!$E$5:$E$504,MATCH($A9&"|"&TEXT(_xlfn.MINIFS(Voortgang!$L$5:$L$504,Voortgang!$B$5:$B$504,$A9),"00"),Voortgang!$M$5:$M$504,0))),"")) | L9: =IF($A9="","",COUNTIFS(Overeenkomsten!$B$5:$B$504,$A9,Overeenkomsten!$E$5:$E$504,"Getekend")) | M9: =IF($A9="","",COUNTIFS(Overeenkomsten!$B$5:$B$504,$A9)-$L9) | N9: =IF($A9="","",COUNTIFS(Bronnen!$B$5:$B$504,$A9,Bronnen!$H$5:$H$504,"Ontvangen")+COUNTIFS(Bronnen!$B$5:$B$504,$A9,Bronnen!$H$5:$H$504,"In analyse")+COUNTIFS(Bronnen!$B$5:$B$504,$A9,Bronnen!$H$5:$H$504,"Verwerkt")) | O9: =IF($A9="","",COUNTIFS(Bronnen!$B$5:$B$504,$A9,Bronnen!$H$5:$H$504,"Ontvangen")+COUNTIFS(Bronnen!$B$5:$B$504,$A9,Bronnen!$H$5:$H$504,"In analyse")) | P9: =IF($A9="","",INDEX(Leads!$Q$5:$Q$504,5))
A10: =IFERROR(IF(INDEX(Leads!$A$5:$A$504,6)="","",INDEX(Leads!$A$5:$A$504,6)),"") | B10: =IF($A10="","",INDEX(Leads!$C$5:$C$504,6)) | C10: =IF($A10="","",INDEX(Leads!$B$5:$B$504,6)) | D10: =IF($A10="","",INDEX(Leads!$J$5:$J$504,6)) | E10: =IF($A10="","",INDEX(Leads!$L$5:$L$504,6)) | F10: =IF($A10="","",COUNTIFS(Voortgang!$B$5:$B$504,$A10)) | G10: =IF($A10="","",COUNTIFS(Voortgang!$B$5:$B$504,$A10,Voortgang!$G$5:$G$504,"Gereed")) | H10: =IF($A10="","",COUNTIFS(Voortgang!$B$5:$B$504,$A10,Voortgang!$G$5:$G$504,"Loopt")) | I10: =IF($A10="","",COUNTIFS(Voortgang!$B$5:$B$504,$A10,Voortgang!$G$5:$G$504,"Geblokkeerd")) | J10: =IF($A10="","",IFERROR($G10/($F10-COUNTIFS(Voortgang!$B$5:$B$504,$A10,Voortgang!$G$5:$G$504,"Niet van toepassing")),"")) | K10: =IF($A10="","",IFERROR(IF(_xlfn.MINIFS(Voortgang!$L$5:$L$504,Voortgang!$B$5:$B$504,$A10)=9999,"Alle stappen afgerond",INDEX(Voortgang!$E$5:$E$504,MATCH($A10&"|"&TEXT(_xlfn.MINIFS(Voortgang!$L$5:$L$504,Voortgang!$B$5:$B$504,$A10),"00"),Voortgang!$M$5:$M$504,0))),"")) | L10: =IF($A10="","",COUNTIFS(Overeenkomsten!$B$5:$B$504,$A10,Overeenkomsten!$E$5:$E$504,"Getekend")) | M10: =IF($A10="","",COUNTIFS(Overeenkomsten!$B$5:$B$504,$A10)-$L10) | N10: =IF($A10="","",COUNTIFS(Bronnen!$B$5:$B$504,$A10,Bronnen!$H$5:$H$504,"Ontvangen")+COUNTIFS(Bronnen!$B$5:$B$504,$A10,Bronnen!$H$5:$H$504,"In analyse")+COUNTIFS(Bronnen!$B$5:$B$504,$A10,Bronnen!$H$5:$H$504,"Verwerkt")) | O10: =IF($A10="","",COUNTIFS(Bronnen!$B$5:$B$504,$A10,Bronnen!$H$5:$H$504,"Ontvangen")+COUNTIFS(Bronnen!$B$5:$B$504,$A10,Bronnen!$H$5:$H$504,"In analyse")) | P10: =IF($A10="","",INDEX(Leads!$Q$5:$Q$504,6))
A11: =IFERROR(IF(INDEX(Leads!$A$5:$A$504,7)="","",INDEX(Leads!$A$5:$A$504,7)),"") | B11: =IF($A11="","",INDEX(Leads!$C$5:$C$504,7)) | C11: =IF($A11="","",INDEX(Leads!$B$5:$B$504,7)) | D11: =IF($A11="","",INDEX(Leads!$J$5:$J$504,7)) | E11: =IF($A11="","",INDEX(Leads!$L$5:$L$504,7)) | F11: =IF($A11="","",COUNTIFS(Voortgang!$B$5:$B$504,$A11)) | G11: =IF($A11="","",COUNTIFS(Voortgang!$B$5:$B$504,$A11,Voortgang!$G$5:$G$504,"Gereed")) | H11: =IF($A11="","",COUNTIFS(Voortgang!$B$5:$B$504,$A11,Voortgang!$G$5:$G$504,"Loopt")) | I11: =IF($A11="","",COUNTIFS(Voortgang!$B$5:$B$504,$A11,Voortgang!$G$5:$G$504,"Geblokkeerd")) | J11: =IF($A11="","",IFERROR($G11/($F11-COUNTIFS(Voortgang!$B$5:$B$504,$A11,Voortgang!$G$5:$G$504,"Niet van toepassing")),"")) | K11: =IF($A11="","",IFERROR(IF(_xlfn.MINIFS(Voortgang!$L$5:$L$504,Voortgang!$B$5:$B$504,$A11)=9999,"Alle stappen afgerond",INDEX(Voortgang!$E$5:$E$504,MATCH($A11&"|"&TEXT(_xlfn.MINIFS(Voortgang!$L$5:$L$504,Voortgang!$B$5:$B$504,$A11),"00"),Voortgang!$M$5:$M$504,0))),"")) | L11: =IF($A11="","",COUNTIFS(Overeenkomsten!$B$5:$B$504,$A11,Overeenkomsten!$E$5:$E$504,"Getekend")) | M11: =IF($A11="","",COUNTIFS(Overeenkomsten!$B$5:$B$504,$A11)-$L11) | N11: =IF($A11="","",COUNTIFS(Bronnen!$B$5:$B$504,$A11,Bronnen!$H$5:$H$504,"Ontvangen")+COUNTIFS(Bronnen!$B$5:$B$504,$A11,Bronnen!$H$5:$H$504,"In analyse")+COUNTIFS(Bronnen!$B$5:$B$504,$A11,Bronnen!$H$5:$H$504,"Verwerkt")) | O11: =IF($A11="","",COUNTIFS(Bronnen!$B$5:$B$504,$A11,Bronnen!$H$5:$H$504,"Ontvangen")+COUNTIFS(Bronnen!$B$5:$B$504,$A11,Bronnen!$H$5:$H$504,"In analyse")) | P11: =IF($A11="","",INDEX(Leads!$Q$5:$Q$504,7))
A12: =IFERROR(IF(INDEX(Leads!$A$5:$A$504,8)="","",INDEX(Leads!$A$5:$A$504,8)),"") | B12: =IF($A12="","",INDEX(Leads!$C$5:$C$504,8)) | C12: =IF($A12="","",INDEX(Leads!$B$5:$B$504,8)) | D12: =IF($A12="","",INDEX(Leads!$J$5:$J$504,8)) | E12: =IF($A12="","",INDEX(Leads!$L$5:$L$504,8)) | F12: =IF($A12="","",COUNTIFS(Voortgang!$B$5:$B$504,$A12)) | G12: =IF($A12="","",COUNTIFS(Voortgang!$B$5:$B$504,$A12,Voortgang!$G$5:$G$504,"Gereed")) | H12: =IF($A12="","",COUNTIFS(Voortgang!$B$5:$B$504,$A12,Voortgang!$G$5:$G$504,"Loopt")) | I12: =IF($A12="","",COUNTIFS(Voortgang!$B$5:$B$504,$A12,Voortgang!$G$5:$G$504,"Geblokkeerd")) | J12: =IF($A12="","",IFERROR($G12/($F12-COUNTIFS(Voortgang!$B$5:$B$504,$A12,Voortgang!$G$5:$G$504,"Niet van toepassing")),"")) | K12: =IF($A12="","",IFERROR(IF(_xlfn.MINIFS(Voortgang!$L$5:$L$504,Voortgang!$B$5:$B$504,$A12)=9999,"Alle stappen afgerond",INDEX(Voortgang!$E$5:$E$504,MATCH($A12&"|"&TEXT(_xlfn.MINIFS(Voortgang!$L$5:$L$504,Voortgang!$B$5:$B$504,$A12),"00"),Voortgang!$M$5:$M$504,0))),"")) | L12: =IF($A12="","",COUNTIFS(Overeenkomsten!$B$5:$B$504,$A12,Overeenkomsten!$E$5:$E$504,"Getekend")) | M12: =IF($A12="","",COUNTIFS(Overeenkomsten!$B$5:$B$504,$A12)-$L12) | N12: =IF($A12="","",COUNTIFS(Bronnen!$B$5:$B$504,$A12,Bronnen!$H$5:$H$504,"Ontvangen")+COUNTIFS(Bronnen!$B$5:$B$504,$A12,Bronnen!$H$5:$H$504,"In analyse")+COUNTIFS(Bronnen!$B$5:$B$504,$A12,Bronnen!$H$5:$H$504,"Verwerkt")) | O12: =IF($A12="","",COUNTIFS(Bronnen!$B$5:$B$504,$A12,Bronnen!$H$5:$H$504,"Ontvangen")+COUNTIFS(Bronnen!$B$5:$B$504,$A12,Bronnen!$H$5:$H$504,"In analyse")) | P12: =IF($A12="","",INDEX(Leads!$Q$5:$Q$504,8))
A13: =IFERROR(IF(INDEX(Leads!$A$5:$A$504,9)="","",INDEX(Leads!$A$5:$A$504,9)),"") | B13: =IF($A13="","",INDEX(Leads!$C$5:$C$504,9)) | C13: =IF($A13="","",INDEX(Leads!$B$5:$B$504,9)) | D13: =IF($A13="","",INDEX(Leads!$J$5:$J$504,9)) | E13: =IF($A13="","",INDEX(Leads!$L$5:$L$504,9)) | F13: =IF($A13="","",COUNTIFS(Voortgang!$B$5:$B$504,$A13)) | G13: =IF($A13="","",COUNTIFS(Voortgang!$B$5:$B$504,$A13,Voortgang!$G$5:$G$504,"Gereed")) | H13: =IF($A13="","",COUNTIFS(Voortgang!$B$5:$B$504,$A13,Voortgang!$G$5:$G$504,"Loopt")) | I13: =IF($A13="","",COUNTIFS(Voortgang!$B$5:$B$504,$A13,Voortgang!$G$5:$G$504,"Geblokkeerd")) | J13: =IF($A13="","",IFERROR($G13/($F13-COUNTIFS(Voortgang!$B$5:$B$504,$A13,Voortgang!$G$5:$G$504,"Niet van toepassing")),"")) | K13: =IF($A13="","",IFERROR(IF(_xlfn.MINIFS(Voortgang!$L$5:$L$504,Voortgang!$B$5:$B$504,$A13)=9999,"Alle stappen afgerond",INDEX(Voortgang!$E$5:$E$504,MATCH($A13&"|"&TEXT(_xlfn.MINIFS(Voortgang!$L$5:$L$504,Voortgang!$B$5:$B$504,$A13),"00"),Voortgang!$M$5:$M$504,0))),"")) | L13: =IF($A13="","",COUNTIFS(Overeenkomsten!$B$5:$B$504,$A13,Overeenkomsten!$E$5:$E$504,"Getekend")) | M13: =IF($A13="","",COUNTIFS(Overeenkomsten!$B$5:$B$504,$A13)-$L13) | N13: =IF($A13="","",COUNTIFS(Bronnen!$B$5:$B$504,$A13,Bronnen!$H$5:$H$504,"Ontvangen")+COUNTIFS(Bronnen!$B$5:$B$504,$A13,Bronnen!$H$5:$H$504,"In analyse")+COUNTIFS(Bronnen!$B$5:$B$504,$A13,Bronnen!$H$5:$H$504,"Verwerkt")) | O13: =IF($A13="","",COUNTIFS(Bronnen!$B$5:$B$504,$A13,Bronnen!$H$5:$H$504,"Ontvangen")+COUNTIFS(Bronnen!$B$5:$B$504,$A13,Bronnen!$H$5:$H$504,"In analyse")) | P13: =IF($A13="","",INDEX(Leads!$Q$5:$Q$504,9))
A14: =IFERROR(IF(INDEX(Leads!$A$5:$A$504,10)="","",INDEX(Leads!$A$5:$A$504,10)),"") | B14: =IF($A14="","",INDEX(Leads!$C$5:$C$504,10)) | C14: =IF($A14="","",INDEX(Leads!$B$5:$B$504,10)) | D14: =IF($A14="","",INDEX(Leads!$J$5:$J$504,10)) | E14: =IF($A14="","",INDEX(Leads!$L$5:$L$504,10)) | F14: =IF($A14="","",COUNTIFS(Voortgang!$B$5:$B$504,$A14)) | G14: =IF($A14="","",COUNTIFS(Voortgang!$B$5:$B$504,$A14,Voortgang!$G$5:$G$504,"Gereed")) | H14: =IF($A14="","",COUNTIFS(Voortgang!$B$5:$B$504,$A14,Voortgang!$G$5:$G$504,"Loopt")) | I14: =IF($A14="","",COUNTIFS(Voortgang!$B$5:$B$504,$A14,Voortgang!$G$5:$G$504,"Geblokkeerd")) | J14: =IF($A14="","",IFERROR($G14/($F14-COUNTIFS(Voortgang!$B$5:$B$504,$A14,Voortgang!$G$5:$G$504,"Niet van toepassing")),"")) | K14: =IF($A14="","",IFERROR(IF(_xlfn.MINIFS(Voortgang!$L$5:$L$504,Voortgang!$B$5:$B$504,$A14)=9999,"Alle stappen afgerond",INDEX(Voortgang!$E$5:$E$504,MATCH($A14&"|"&TEXT(_xlfn.MINIFS(Voortgang!$L$5:$L$504,Voortgang!$B$5:$B$504,$A14),"00"),Voortgang!$M$5:$M$504,0))),"")) | L14: =IF($A14="","",COUNTIFS(Overeenkomsten!$B$5:$B$504,$A14,Overeenkomsten!$E$5:$E$504,"Getekend")) | M14: =IF($A14="","",COUNTIFS(Overeenkomsten!$B$5:$B$504,$A14)-$L14) | N14: =IF($A14="","",COUNTIFS(Bronnen!$B$5:$B$504,$A14,Bronnen!$H$5:$H$504,"Ontvangen")+COUNTIFS(Bronnen!$B$5:$B$504,$A14,Bronnen!$H$5:$H$504,"In analyse")+COUNTIFS(Bronnen!$B$5:$B$504,$A14,Bronnen!$H$5:$H$504,"Verwerkt")) | O14: =IF($A14="","",COUNTIFS(Bronnen!$B$5:$B$504,$A14,Bronnen!$H$5:$H$504,"Ontvangen")+COUNTIFS(Bronnen!$B$5:$B$504,$A14,Bronnen!$H$5:$H$504,"In analyse")) | P14: =IF($A14="","",INDEX(Leads!$Q$5:$Q$504,10))
A15: =IFERROR(IF(INDEX(Leads!$A$5:$A$504,11)="","",INDEX(Leads!$A$5:$A$504,11)),"") | B15: =IF($A15="","",INDEX(Leads!$C$5:$C$504,11)) | C15: =IF($A15="","",INDEX(Leads!$B$5:$B$504,11)) | D15: =IF($A15="","",INDEX(Leads!$J$5:$J$504,11)) | E15: =IF($A15="","",INDEX(Leads!$L$5:$L$504,11)) | F15: =IF($A15="","",COUNTIFS(Voortgang!$B$5:$B$504,$A15)) | G15: =IF($A15="","",COUNTIFS(Voortgang!$B$5:$B$504,$A15,Voortgang!$G$5:$G$504,"Gereed")) | H15: =IF($A15="","",COUNTIFS(Voortgang!$B$5:$B$504,$A15,Voortgang!$G$5:$G$504,"Loopt")) | I15: =IF($A15="","",COUNTIFS(Voortgang!$B$5:$B$504,$A15,Voortgang!$G$5:$G$504,"Geblokkeerd")) | J15: =IF($A15="","",IFERROR($G15/($F15-COUNTIFS(Voortgang!$B$5:$B$504,$A15,Voortgang!$G$5:$G$504,"Niet van toepassing")),"")) | K15: =IF($A15="","",IFERROR(IF(_xlfn.MINIFS(Voortgang!$L$5:$L$504,Voortgang!$B$5:$B$504,$A15)=9999,"Alle stappen afgerond",INDEX(Voortgang!$E$5:$E$504,MATCH($A15&"|"&TEXT(_xlfn.MINIFS(Voortgang!$L$5:$L$504,Voortgang!$B$5:$B$504,$A15),"00"),Voortgang!$M$5:$M$504,0))),"")) | L15: =IF($A15="","",COUNTIFS(Overeenkomsten!$B$5:$B$504,$A15,Overeenkomsten!$E$5:$E$504,"Getekend")) | M15: =IF($A15="","",COUNTIFS(Overeenkomsten!$B$5:$B$504,$A15)-$L15) | N15: =IF($A15="","",COUNTIFS(Bronnen!$B$5:$B$504,$A15,Bronnen!$H$5:$H$504,"Ontvangen")+COUNTIFS(Bronnen!$B$5:$B$504,$A15,Bronnen!$H$5:$H$504,"In analyse")+COUNTIFS(Bronnen!$B$5:$B$504,$A15,Bronnen!$H$5:$H$504,"Verwerkt")) | O15: =IF($A15="","",COUNTIFS(Bronnen!$B$5:$B$504,$A15,Bronnen!$H$5:$H$504,"Ontvangen")+COUNTIFS(Bronnen!$B$5:$B$504,$A15,Bronnen!$H$5:$H$504,"In analyse")) | P15: =IF($A15="","",INDEX(Leads!$Q$5:$Q$504,11))
A16: =IFERROR(IF(INDEX(Leads!$A$5:$A$504,12)="","",INDEX(Leads!$A$5:$A$504,12)),"") | B16: =IF($A16="","",INDEX(Leads!$C$5:$C$504,12)) | C16: =IF($A16="","",INDEX(Leads!$B$5:$B$504,12)) | D16: =IF($A16="","",INDEX(Leads!$J$5:$J$504,12)) | E16: =IF($A16="","",INDEX(Leads!$L$5:$L$504,12)) | F16: =IF($A16="","",COUNTIFS(Voortgang!$B$5:$B$504,$A16)) | G16: =IF($A16="","",COUNTIFS(Voortgang!$B$5:$B$504,$A16,Voortgang!$G$5:$G$504,"Gereed")) | H16: =IF($A16="","",COUNTIFS(Voortgang!$B$5:$B$504,$A16,Voortgang!$G$5:$G$504,"Loopt")) | I16: =IF($A16="","",COUNTIFS(Voortgang!$B$5:$B$504,$A16,Voortgang!$G$5:$G$504,"Geblokkeerd")) | J16: =IF($A16="","",IFERROR($G16/($F16-COUNTIFS(Voortgang!$B$5:$B$504,$A16,Voortgang!$G$5:$G$504,"Niet van toepassing")),"")) | K16: =IF($A16="","",IFERROR(IF(_xlfn.MINIFS(Voortgang!$L$5:$L$504,Voortgang!$B$5:$B$504,$A16)=9999,"Alle stappen afgerond",INDEX(Voortgang!$E$5:$E$504,MATCH($A16&"|"&TEXT(_xlfn.MINIFS(Voortgang!$L$5:$L$504,Voortgang!$B$5:$B$504,$A16),"00"),Voortgang!$M$5:$M$504,0))),"")) | L16: =IF($A16="","",COUNTIFS(Overeenkomsten!$B$5:$B$504,$A16,Overeenkomsten!$E$5:$E$504,"Getekend")) | M16: =IF($A16="","",COUNTIFS(Overeenkomsten!$B$5:$B$504,$A16)-$L16) | N16: =IF($A16="","",COUNTIFS(Bronnen!$B$5:$B$504,$A16,Bronnen!$H$5:$H$504,"Ontvangen")+COUNTIFS(Bronnen!$B$5:$B$504,$A16,Bronnen!$H$5:$H$504,"In analyse")+COUNTIFS(Bronnen!$B$5:$B$504,$A16,Bronnen!$H$5:$H$504,"Verwerkt")) | O16: =IF($A16="","",COUNTIFS(Bronnen!$B$5:$B$504,$A16,Bronnen!$H$5:$H$504,"Ontvangen")+COUNTIFS(Bronnen!$B$5:$B$504,$A16,Bronnen!$H$5:$H$504,"In analyse")) | P16: =IF($A16="","",INDEX(Leads!$Q$5:$Q$504,12))
A17: =IFERROR(IF(INDEX(Leads!$A$5:$A$504,13)="","",INDEX(Leads!$A$5:$A$504,13)),"") | B17: =IF($A17="","",INDEX(Leads!$C$5:$C$504,13)) | C17: =IF($A17="","",INDEX(Leads!$B$5:$B$504,13)) | D17: =IF($A17="","",INDEX(Leads!$J$5:$J$504,13)) | E17: =IF($A17="","",INDEX(Leads!$L$5:$L$504,13)) | F17: =IF($A17="","",COUNTIFS(Voortgang!$B$5:$B$504,$A17)) | G17: =IF($A17="","",COUNTIFS(Voortgang!$B$5:$B$504,$A17,Voortgang!$G$5:$G$504,"Gereed")) | H17: =IF($A17="","",COUNTIFS(Voortgang!$B$5:$B$504,$A17,Voortgang!$G$5:$G$504,"Loopt")) | I17: =IF($A17="","",COUNTIFS(Voortgang!$B$5:$B$504,$A17,Voortgang!$G$5:$G$504,"Geblokkeerd")) | J17: =IF($A17="","",IFERROR($G17/($F17-COUNTIFS(Voortgang!$B$5:$B$504,$A17,Voortgang!$G$5:$G$504,"Niet van toepassing")),"")) | K17: =IF($A17="","",IFERROR(IF(_xlfn.MINIFS(Voortgang!$L$5:$L$504,Voortgang!$B$5:$B$504,$A17)=9999,"Alle stappen afgerond",INDEX(Voortgang!$E$5:$E$504,MATCH($A17&"|"&TEXT(_xlfn.MINIFS(Voortgang!$L$5:$L$504,Voortgang!$B$5:$B$504,$A17),"00"),Voortgang!$M$5:$M$504,0))),"")) | L17: =IF($A17="","",COUNTIFS(Overeenkomsten!$B$5:$B$504,$A17,Overeenkomsten!$E$5:$E$504,"Getekend")) | M17: =IF($A17="","",COUNTIFS(Overeenkomsten!$B$5:$B$504,$A17)-$L17) | N17: =IF($A17="","",COUNTIFS(Bronnen!$B$5:$B$504,$A17,Bronnen!$H$5:$H$504,"Ontvangen")+COUNTIFS(Bronnen!$B$5:$B$504,$A17,Bronnen!$H$5:$H$504,"In analyse")+COUNTIFS(Bronnen!$B$5:$B$504,$A17,Bronnen!$H$5:$H$504,"Verwerkt")) | O17: =IF($A17="","",COUNTIFS(Bronnen!$B$5:$B$504,$A17,Bronnen!$H$5:$H$504,"Ontvangen")+COUNTIFS(Bronnen!$B$5:$B$504,$A17,Bronnen!$H$5:$H$504,"In analyse")) | P17: =IF($A17="","",INDEX(Leads!$Q$5:$Q$504,13))
A18: =IFERROR(IF(INDEX(Leads!$A$5:$A$504,14)="","",INDEX(Leads!$A$5:$A$504,14)),"") | B18: =IF($A18="","",INDEX(Leads!$C$5:$C$504,14)) | C18: =IF($A18="","",INDEX(Leads!$B$5:$B$504,14)) | D18: =IF($A18="","",INDEX(Leads!$J$5:$J$504,14)) | E18: =IF($A18="","",INDEX(Leads!$L$5:$L$504,14)) | F18: =IF($A18="","",COUNTIFS(Voortgang!$B$5:$B$504,$A18)) | G18: =IF($A18="","",COUNTIFS(Voortgang!$B$5:$B$504,$A18,Voortgang!$G$5:$G$504,"Gereed")) | H18: =IF($A18="","",COUNTIFS(Voortgang!$B$5:$B$504,$A18,Voortgang!$G$5:$G$504,"Loopt")) | I18: =IF($A18="","",COUNTIFS(Voortgang!$B$5:$B$504,$A18,Voortgang!$G$5:$G$504,"Geblokkeerd")) | J18: =IF($A18="","",IFERROR($G18/($F18-COUNTIFS(Voortgang!$B$5:$B$504,$A18,Voortgang!$G$5:$G$504,"Niet van toepassing")),"")) | K18: =IF($A18="","",IFERROR(IF(_xlfn.MINIFS(Voortgang!$L$5:$L$504,Voortgang!$B$5:$B$504,$A18)=9999,"Alle stappen afgerond",INDEX(Voortgang!$E$5:$E$504,MATCH($A18&"|"&TEXT(_xlfn.MINIFS(Voortgang!$L$5:$L$504,Voortgang!$B$5:$B$504,$A18),"00"),Voortgang!$M$5:$M$504,0))),"")) | L18: =IF($A18="","",COUNTIFS(Overeenkomsten!$B$5:$B$504,$A18,Overeenkomsten!$E$5:$E$504,"Getekend")) | M18: =IF($A18="","",COUNTIFS(Overeenkomsten!$B$5:$B$504,$A18)-$L18) | N18: =IF($A18="","",COUNTIFS(Bronnen!$B$5:$B$504,$A18,Bronnen!$H$5:$H$504,"Ontvangen")+COUNTIFS(Bronnen!$B$5:$B$504,$A18,Bronnen!$H$5:$H$504,"In analyse")+COUNTIFS(Bronnen!$B$5:$B$504,$A18,Bronnen!$H$5:$H$504,"Verwerkt")) | O18: =IF($A18="","",COUNTIFS(Bronnen!$B$5:$B$504,$A18,Bronnen!$H$5:$H$504,"Ontvangen")+COUNTIFS(Bronnen!$B$5:$B$504,$A18,Bronnen!$H$5:$H$504,"In analyse")) | P18: =IF($A18="","",INDEX(Leads!$Q$5:$Q$504,14))
A19: =IFERROR(IF(INDEX(Leads!$A$5:$A$504,15)="","",INDEX(Leads!$A$5:$A$504,15)),"") | B19: =IF($A19="","",INDEX(Leads!$C$5:$C$504,15)) | C19: =IF($A19="","",INDEX(Leads!$B$5:$B$504,15)) | D19: =IF($A19="","",INDEX(Leads!$J$5:$J$504,15)) | E19: =IF($A19="","",INDEX(Leads!$L$5:$L$504,15)) | F19: =IF($A19="","",COUNTIFS(Voortgang!$B$5:$B$504,$A19)) | G19: =IF($A19="","",COUNTIFS(Voortgang!$B$5:$B$504,$A19,Voortgang!$G$5:$G$504,"Gereed")) | H19: =IF($A19="","",COUNTIFS(Voortgang!$B$5:$B$504,$A19,Voortgang!$G$5:$G$504,"Loopt")) | I19: =IF($A19="","",COUNTIFS(Voortgang!$B$5:$B$504,$A19,Voortgang!$G$5:$G$504,"Geblokkeerd")) | J19: =IF($A19="","",IFERROR($G19/($F19-COUNTIFS(Voortgang!$B$5:$B$504,$A19,Voortgang!$G$5:$G$504,"Niet van toepassing")),"")) | K19: =IF($A19="","",IFERROR(IF(_xlfn.MINIFS(Voortgang!$L$5:$L$504,Voortgang!$B$5:$B$504,$A19)=9999,"Alle stappen afgerond",INDEX(Voortgang!$E$5:$E$504,MATCH($A19&"|"&TEXT(_xlfn.MINIFS(Voortgang!$L$5:$L$504,Voortgang!$B$5:$B$504,$A19),"00"),Voortgang!$M$5:$M$504,0))),"")) | L19: =IF($A19="","",COUNTIFS(Overeenkomsten!$B$5:$B$504,$A19,Overeenkomsten!$E$5:$E$504,"Getekend")) | M19: =IF($A19="","",COUNTIFS(Overeenkomsten!$B$5:$B$504,$A19)-$L19) | N19: =IF($A19="","",COUNTIFS(Bronnen!$B$5:$B$504,$A19,Bronnen!$H$5:$H$504,"Ontvangen")+COUNTIFS(Bronnen!$B$5:$B$504,$A19,Bronnen!$H$5:$H$504,"In analyse")+COUNTIFS(Bronnen!$B$5:$B$504,$A19,Bronnen!$H$5:$H$504,"Verwerkt")) | O19: =IF($A19="","",COUNTIFS(Bronnen!$B$5:$B$504,$A19,Bronnen!$H$5:$H$504,"Ontvangen")+COUNTIFS(Bronnen!$B$5:$B$504,$A19,Bronnen!$H$5:$H$504,"In analyse")) | P19: =IF($A19="","",INDEX(Leads!$Q$5:$Q$504,15))
A20: =IFERROR(IF(INDEX(Leads!$A$5:$A$504,16)="","",INDEX(Leads!$A$5:$A$504,16)),"") | B20: =IF($A20="","",INDEX(Leads!$C$5:$C$504,16)) | C20: =IF($A20="","",INDEX(Leads!$B$5:$B$504,16)) | D20: =IF($A20="","",INDEX(Leads!$J$5:$J$504,16)) | E20: =IF($A20="","",INDEX(Leads!$L$5:$L$504,16)) | F20: =IF($A20="","",COUNTIFS(Voortgang!$B$5:$B$504,$A20)) | G20: =IF($A20="","",COUNTIFS(Voortgang!$B$5:$B$504,$A20,Voortgang!$G$5:$G$504,"Gereed")) | H20: =IF($A20="","",COUNTIFS(Voortgang!$B$5:$B$504,$A20,Voortgang!$G$5:$G$504,"Loopt")) | I20: =IF($A20="","",COUNTIFS(Voortgang!$B$5:$B$504,$A20,Voortgang!$G$5:$G$504,"Geblokkeerd")) | J20: =IF($A20="","",IFERROR($G20/($F20-COUNTIFS(Voortgang!$B$5:$B$504,$A20,Voortgang!$G$5:$G$504,"Niet van toepassing")),"")) | K20: =IF($A20="","",IFERROR(IF(_xlfn.MINIFS(Voortgang!$L$5:$L$504,Voortgang!$B$5:$B$504,$A20)=9999,"Alle stappen afgerond",INDEX(Voortgang!$E$5:$E$504,MATCH($A20&"|"&TEXT(_xlfn.MINIFS(Voortgang!$L$5:$L$504,Voortgang!$B$5:$B$504,$A20),"00"),Voortgang!$M$5:$M$504,0))),"")) | L20: =IF($A20="","",COUNTIFS(Overeenkomsten!$B$5:$B$504,$A20,Overeenkomsten!$E$5:$E$504,"Getekend")) | M20: =IF($A20="","",COUNTIFS(Overeenkomsten!$B$5:$B$504,$A20)-$L20) | N20: =IF($A20="","",COUNTIFS(Bronnen!$B$5:$B$504,$A20,Bronnen!$H$5:$H$504,"Ontvangen")+COUNTIFS(Bronnen!$B$5:$B$504,$A20,Bronnen!$H$5:$H$504,"In analyse")+COUNTIFS(Bronnen!$B$5:$B$504,$A20,Bronnen!$H$5:$H$504,"Verwerkt")) | O20: =IF($A20="","",COUNTIFS(Bronnen!$B$5:$B$504,$A20,Bronnen!$H$5:$H$504,"Ontvangen")+COUNTIFS(Bronnen!$B$5:$B$504,$A20,Bronnen!$H$5:$H$504,"In analyse")) | P20: =IF($A20="","",INDEX(Leads!$Q$5:$Q$504,16))
